Workbook

Sheet Ответы на форму (1)
A1: Отметка времени | B1: Адрес электронной почты | C1: Баллы | D1: ExtendedForms Id (skip this field) | E1: Укажите ваш класс | F1: 1. Имеется пять действительных чисел: N,9,5,4,7. При каких значениях N из предложенных медиана будет равна среднему? | G1: 2. Измерен рост 25 человек, рост каждого человека оказался отличным от других. Средний рост оказался равным 160 см. Медиана оказалась равной 155 см. Васин рост в 163 см был ошибочно внесен как 173 см. Как изменится величина среднего роста после исправления ошибки? | H1: 3. Перед вами таблица из демографического отчета города N о количестве детей в семьях. Все семьи города N имеют двух родителей, а все дети проживают со своими родителями. Выберите все верные утверждения, которые можно сделать на основе представленной таблицы. | I1: 4. В 2021 году в стране N пройдут выборы, в которых примут участие всего два кандидата: А и В. Страна состоит из четырёх регионов. Победителем выборов будет тот, кто получит больше голосов суммарно по четырём регионам. Для прогнозирования результатов выборов в каждом из четырёх регионов был проведён предварительный опрос населения (выборки были показательны), результаты которого приведены ниже. Выберите все верные выводы, которые можно сделать по результатам опроса. | J1: 5. В соревновании участвуют 6 команд. В одной букмекерской конторе коэффициенты на победу команд равны 2, 4, 8, 16, 32 и N. Выиграть может только одна команда. Каким должен быть максимальный коэффициент N, чтобы футбольный фанат Саша не смог гарантированно выиграть (считайте, что Саша может делать любое количество ставок у букмекера на любые команды)? | K1: 6. В некоторой стране десятилетиями занимаются выращиванием пшеницы. В таблице приведена урожайность зерна за 10 лет с 2010 по 2019 года в стране N. За все время наблюдений табличные данные за десятилетия не изменялись, то есть в 2000-2009, в 1990-1999 таблицы были идентичными. Данные по 2015 и 2016 годах были потеряны, как и статистика за прошлые годы, но дисперсия и средняя десятилетней выборки были заранее подсчитаны и равны соответственно 176,16 и 29,2. Государство планирует ввести в эксплуатацию новые земли, что приведет к росту урожайности на 10 млн тонн в каждом году. Это значит, что в 2020 году урожай составит 14 + 10 = 24 тонны, в 2021 – 28,8, в 2012 – 33,2 и т. д. Выберите все верные утверждения. | L1: 7. Идеальную монету подбросили 10 раз. Выберите верные утверждения. | M1: 8. Организаторы лотереи желают получать 20 процентов от выручки в виде чистой прибыли, ни больше, ни меньше. Гарантировано, что все билеты будут куплены. Все издержки, кроме непосредственных выплат участникам, считать равными нулю. Шансы выиграть в лотерею представлены в таблице. Государство взимает 20% налог на выручку фирм. Выберите верное утверждение. | N1: 9. В числовом наборе 50 чисел. Если из него выкинуть одно число, то медиана оставшихся чисел будет равна 64, а если другое число, то медиана оставшихся чисел будет равна 48. Чему равна медиана изначального набора? | O1: 10. Перед вами представлена таблица, отражающая проданное количество билетов в процентах по отношению к предыдущему месяцу за 12 месяцев одного года. На основе представленных данных выберите верные суждения. | P1: 11. Перед Вами график того, сколько задач составили Настя, Никита и Марк для олимпиады. Выберите все недостатки этой визуализации (если они есть). | Q1: 12. В казино «El Torro» нельзя сделать ставку меньше 14 тыс. руб. Известно, что Саша сделал в этом казино четыре ставки, их среднее значение равно 29 тыс. руб., а медианное — 30 тыс.руб. Чему равно (в тыс. руб.) максимально возможное значение второй по величине ставки? | R1: 13. Известно, что за июнь, август и сентябрь компания «Помпончик» получила прибыли в размере 30, 42 и 42 тыс. руб., соответственно. Однако значение прибыли в июле было утеряно. Выберите все характеристики, знания которых всегда позволяют однозначно восстановить потерянное значение. | S1: 14. Перед Вами диаграмма, показывающая прибыли компании по производству зерна “Петушкококо” за года с 2016 по 2020. По оценкам экспертов Кости и Саши годовой темп прироста прибыли в 2021 году будет равен среднему значению годовых темпов прироста за указанные выше года. Какую в таком случае прибыль стоит ожидать в 2021 году (выберите ближайшее значение)? | T1: 15.Перед Вами диаграмма, показывающая информацию о росте, весе и поле всех участников детского театрального коллектива "Солнышко". Выберите все верные утверждения, следующие из графика. | U1: 16. Иосиф С. установил следующий план: каждый год производить N литров газированного сладкого напитка П. Известно, что в первый год производство напитка было на 10 процентов меньше требуемого количества. На следующий год производство выросло на 10%. На сколько процентов должно измениться производство (по модулю) в следующем (третьем) году, чтобы выполнить требуемую норму за год? | V1: 17. После теста Юля очень хочет узнать, какое место в группе она занимает понабранному баллу (первое место имеет наибольший балл, последнее —наименьший, соответственно). Всего в группе 5 человек. Оценка за тест может быть лишь целым числом от 0 до 5. Учитель пока не хочет оглашать оценки, но подсказал Юле, что ее балл выше медианного на 2, а мода распределения оценок равна 3. Если два ученика набирают одинаковое количество баллов, то они оба занимают одинаковую позицию в рейтинге (например, если все пятеро наберут 5 баллов, то будет пять первых мест). Какое место может занимать Юля в рейтинге оценок за тест (выберите все варианты)? | W1: 18. Какое/какие из следующих утверждений верны? (1) Если рост человека выше среднего роста всех людей на Земле, то этот человек выше половины людей на Земле. (2) Если человек выше половины людей на Земле, то его рост выше среднего роста всех людей на Земле. (3) Если медианный рост всех людей на Земле меньше, чем средний рост всех людей на Земле, то человек, рост которого превышает средний рост всех людей на Земле, будет выше как минимум половины человечества. | X1: 19. На экзамене Лаура перепутала понятие медиана и среднее и на вопрос “Какое среднее у представленного ряда?” ответила 5. Известно, что ряд состоял из пяти чисел. Известно, что размах этого ряда равен 5, а его мода равна 3. Каким мог быть правильный ответ на заданный Лауре вопрос экзамена (выберите все возможные варианты)? | Y1: 20. Первый график отражает количество летальных исходов (в тысячах) в ДТП в период 1994- 2018 гг., второй - количество исходов с серьезными травмами. Выберите все НЕВЕРНЫЕ утверждения. Источник: https://data.oecd.org/transport/road-accidents.htm | Z1: 21. Перед вами представлена таблица, отражающая годовой выброс парниковых газов в тоннах на человека в странах большой семерки в период 2000-2013 гг. Основываясь на данных, выберите одно верное утверждение. Источник: https://data.oecd.org/air/air-and-ghg-emissions.htm | AA1: 22. Перед вами представлен график, отражающий список стран по возрастанию уровня трудоустройства иностранных резидентов. Выберите все верные утверждения. Источник: https://data.oecd.org/migration/foreign-born-employment.htm | AB1: 23. Сравните и проанализируйте нижеизложенные графики, отражающие математическую и читательскую грамотность среди мальчиков (обозначение кружками) и девочек (треугольники) в баллах. Обратите внимание на то, что результаты по России обозначены красным цветом, а среднее по всем указанным странам - черным цветом. На основе проведенного анализа выберите все верные утверждения. Источник: https://data.oecd.org/pisa/mathematics-performance-pisa.htm https://data.oecd.org/pisa/reading-performance-pisa.htm | AC1: 24. На графике представлено количество учеников, написавших работу на определенный балл (максимальный балл - 14). Какое утверждение верно? | AD1: 25. Даны 3 числа: X, Y и 10. Известно, что среднее арифметическое этих трёх чисел равно 10, а коэффициент вариации равен 0,6. Найдите значения, которые могут принимать X и Y. | AE1: 26. Даны 4 выборки данных по одному эксперименту, состоящие из 4 различных наблюдений в каждой выборке. В каждой выборке наблюдается положительная линейная корреляция, при этом коэффициент наклона линии тренда, построенной для каждой отдельной выборки, больше, чем для предыдущей (наклон линии тренда второй выборки больше, чем первой и тд). Какое утверждение верно?
A2: 44359.972 | B2: micro.fascinated@gmail.com | C2: 72 | D2: 93a8ba0a-dc8d-4389-851e-66f3474a1ab9 | E2: 10 | F2: 10, 6,25, 0 | G2: Увеличится | H2: Медианное количество детей в семье - 2 ребенка, Среднее количество детей в семье меньше медианного, Мода числа детей в семье равняется 3, В городе N родителей больше, чем детей, При сохранении данных статистических показателей в городе N на протяжении длительного времени, можно будет говорить об отрицательном естественном приросте населения | I2: Если бы все воздержавшиеся от ответа поддержали бы кандидата Б, то он точно бы имел большее количество поддерживающих его опрошенных, нежили А, Среднее значение опрошенных, поддерживающих кандидата А, в регионах 1, 2 и 4 равно 63,8% | J2: 32 | K2: Средняя не изменится, Дисперсия не изменится, Невозможно определить изменение дисперсии, так как не хватает данных сразу по двум годам. | L2: Вероятность того, что орел выпадет ровно 5 раз равна 0,5, Вероятность того, что орел выпадет ровно 9 раз меньше одного процента, Вероятность того, что орел выпадет более 5 раз выше, чем вероятность того, что он выпадет меньше пяти раз | M2: Цена билета равна 330 руб. | N2: 56 | O2: Медиана располагается в промежутке [86;95], Моды у данного распределения нет, Количество билетов, проданное в декабре представленного года более чем в 1,5 раза меньше, чем количество билетов, проданное в декабре предыдущего года | P2: Сдвиг шкалы, Непропорциональное масштабирование, Использование процентов вместо абсолютных величин | Q2: 42 | R2: Среднее значение прибылей за рассматриваемые четыре месяца | S2: 228 | T2: Данный тип диаграммы называется диаграммой рассеивания, Если в коллектив придет девочка весом в 54 кг, то медианный вес девочек не изменится | U2: Приблизительно на 1% | V2: 1 | W2: только (3) | X2: 5 | Y2: Исходя из двух графиков, можно сделать вывод о том, что в Японии в среднем случается больше ДТП, чем в России, В Японии разброс значений количества летальных исходов в целом ниже, нежели разброс | Z2: Медианное значение выбросов в Великобритании в период с 2001 по 2011 включительно составляет 8.80 | AA2: В развитых странах ситуация с трудоустройством иностранных резидентов, в целом, обстоит лучше, нежели в развивающихся, Исландия - самая привлекательная страна для мигрантов, Самый высокий показатель трудоустройства не означает того, что в Исландии самая большая доля трудоспособного иностранного населения по сравнению с другими странами, Среднее значение уровня вовлеченности в рабочую силу в группе среди 5 лидеров примерно на 25% выше, нежели среднее в группе среди 5 аутсайдеров, Размах выборки составляет примерно 0,35 | AB2: Разброс результатов тестирования между полами сильнее при исследовании уровня читательской грамотности, нежели математической, В обоих случаях баллы российских участников находятся левее среднего арифметического баллов по анализируемым странам | AC2: Третий квартиль равен 11 | AD2: 13, 7 | AE2: Нет верных утверждений
A3: 44362.945 | B3: egorpranikov39562@gmail.com | C3: 0 | D3: 93aeb644-3242-4cce-839d-7872dea3ad0b | E3: 9 | F3: 6,25, 9 | G3: Увеличится
A4: 44363.731 | B4: utygo@mail.ru | C4: 3 | D4: 93b03888-8a36-49d3-b75d-1b94968305ac | E4: 9 | F4: 0, 6,25, 9 | G4: Может как увеличиться, так и уменьшиться | H4: Среднее количество детей в семье меньше медианного, Мода числа детей в семье равняется 3, В городе N родителей больше, чем детей | I4: Более половины опрошенных поддерживает кандидата А, Медианное значение опрошенных, поддерживающих кандидата В, в регионах равно 41,1%, Если бы все воздержавшиеся от ответа поддержали бы кандидата Б, то он точно бы имел большее количество поддерживающих его опрошенных, нежили А, Среднее значение опрошенных, поддерживающих кандидата А, в регионах 1, 2 и 4 равно 63,8% | J4: 32 | K4: Средняя не изменится, Дисперсия не изменится | L4: Вероятность того, что орел выпадет ровно 9 раз меньше одного процента, Вероятность того, что орел выпадет более 5 раз выше, чем вероятность того, что он выпадет меньше пяти раз | M4: Цена билета равна 275 руб. | N4: 54 | O4: Медиана располагается в промежутке [86;95], Количество билетов, проданное в декабре представленного года более чем в 1,5 раза меньше, чем количество билетов, проданное в декабре предыдущего года | P4: Использование процентов вместо абсолютных величин, Нет недостатков | Q4: 46 | R4: Мода прибылей за рассматриваемые четыре месяца, Стандартное отклонение прибылей за рассматриваемые четыре месяца | S4: 220 | T4: Мода роста выборки из всех участников коллектива равна 58 см., Вес бóльшей части девочек превышает средний вес мальчиков | U4: Среди предложенных вариантов нет верного | V4: 4 | W4: только (2) и (3) | X4: 4,4, 4,8 | Y4: Исходя из данных графиков, Австралия - самая безопасная страна для автовождения из представленных, Показатель летальных исходов в России наиболее меняющийся | Z4: В США наблюдается тренд на снижение количества выбросов парниковых газов на человека | AA4: Исландия - самая привлекательная страна для мигрантов, Размах выборки составляет примерно 0,35 | AB4: Разброс результатов тестирования между полами сильнее при исследовании уровня читательской грамотности, нежели математической, Результаты российских участников примерно на 10 процентных пункта меньше среднего уровня читательской грамотности | AC4: Третий квартиль равен 11 | AD4: 13, 7 | AE4: Коэффициент корреляции Пирсона будет иметь больше значение в случае с объединённой выборкой из первой и четвёртой выборками, чем аналогичный коэффициент Пирсона выборки, состоящей из второй и третьей выборок
A5: 44363.753 | B5: danya.palatkin@yandex.ru | C5: 3 | D5: 93b038a5-2dbc-4f2b-9076-fca1f75d3564 | E5: 9 | F5: 0, 6,25, 9 | G5: Может как увеличиться, так и уменьшиться | H5: Медианное количество детей в семье - 2 ребенка | I5: Медианное значение опрошенных, поддерживающих кандидата В, в регионах равно 41,1% | J5: 64 | K5: Средняя будет равна 39,2 | L5: Вероятность того, что орел выпадет 4 раза не равна вероятности выпадения орла 6 раз | M5: Средний выигрыш будет равен 400 руб. | N5: 56 | O5: Медиана располагается в промежутке [86;95] | P5: Сдвиг шкалы | Q5: 42 | R5: Стандартное отклонение прибылей за рассматриваемые четыре месяца | S5: 220 | T5: Мода роста выборки из всех участников коллектива равна 58 см. | U5: Приблизительно на 2% | V5: 1 | W5: только (1) и (2) | X5: 4,4, 5,6 | Y5: Исходя из двух графиков, можно сделать вывод о том, что в Японии в среднем случается больше ДТП, чем в России | Z5: В Германии разброс значений выбросов в 2000-2013 был больше, нежели в Великобритании | AA5: Среднее значение уровня вовлеченности в рабочую силу в группе среди 5 лидеров примерно на 25% выше, нежели среднее в группе среди 5 аутсайдеров | AB5: В обоих случаях баллы российских участников находятся левее среднего арифметического баллов по анализируемым странам | AC5: Медиана равна 5 | AD5: 5, 15 | AE5: Если предположить, что всего было зафиксировано 30 наблюдений, то выборку, представляющую собой объединение 4-х выборок, представленных выше, точно можно назвать более репрезентативной, чем каждую из вышеупомянутых выборок по отдельности
A6: 44363.816 | B6: catya.mentyukova@yandex.ru | C6: 23 | D6: 93b07103-f970-4192-bb90-bfecea94b906 | E6: 11 | F6: 10, 6,25, 0 | G6: Уменьшится | H6: Медианное количество детей в семье - 2 ребенка, В городе N родителей больше, чем детей, При сохранении данных статистических показателей в городе N на протяжении длительного времени, можно будет говорить об отрицательном естественном приросте населения | I6: Среднее значение опрошенных, поддерживающих кандидата А, в регионах 1, 2 и 4 равно 63,8% | J6: 16 | K6: Средняя будет равна 39,2, Дисперсия не изменится | L6: Вероятность того, что орел выпадет ровно 9 раз меньше одного процента | M6: Среди предложенных выше ответов нет верного | N6: 56 | O6: Медиана располагается в промежутке [86;95], Моды у данного распределения нет, Количество билетов, проданное в декабре представленного года более чем в 1,5 раза меньше, чем количество билетов, проданное в декабре предыдущего года | P6: Сдвиг шкалы, Непропорциональное масштабирование, Использование процентов вместо абсолютных величин | Q6: 42 | R6: Среднее значение прибылей за рассматриваемые четыре месяца | S6: 228 | T6: Данный тип диаграммы называется диаграммой рассеивания, Если в коллектив придет девочка весом в 54 кг, то медианный вес девочек не изменится | U6: Приблизительно на 1% | V6: 1 | W6: только (3) | X6: 5.2 | Y6: Исходя из двух графиков, можно сделать вывод о том, что в Японии в среднем случается больше ДТП, чем в России, Исходя из данных графиков, Австралия - самая безопасная страна для автовождения из представленных | Z6: Медианное значение выбросов в Великобритании в период с 2001 по 2011 включительно составляет 8.80 | AA6: В развитых странах ситуация с трудоустройством иностранных резидентов, в целом, обстоит лучше, нежели в развивающихся, Самый высокий показатель трудоустройства не означает того, что в Исландии самая большая доля трудоспособного иностранного населения по сравнению с другими странами, Среднее значение уровня вовлеченности в рабочую силу в группе среди 5 лидеров примерно на 25% выше, нежели среднее в группе среди 5 аутсайдеров | AB6: Разброс результатов тестирования между полами сильнее при исследовании уровня читательской грамотности, нежели математической, В обоих случаях баллы российских участников находятся левее среднего арифметического баллов по анализируемым странам | AC6: Третий квартиль равен 11 | AD6: 3, 17 | AE6: Нет верных утверждений
A7: 44363.823 | B7: atremy.rybkin@gmail.com | C7: 6 | D7: 93b06758-5804-4d72-a381-0ba22fd5803b | E7: 9 | F7: 10, 6,25, 0 | G7: Уменьшится | H7: Медианное количество детей в семье - 2 ребенка, Среднее количество детей в семье меньше медианного, В городе N родителей больше, чем детей, При сохранении данных статистических показателей в городе N на протяжении длительного времени, можно будет говорить об отрицательном естественном приросте населения | I7: В среднем в регионах воздерживаются от ответа менее 4,5% опрошенных | J7: 4 | K7: Средняя будет равна 39,2, Невозможно определить изменение дисперсии, так как не хватает данных сразу по двум годам. | L7: Вероятность того, что орел выпадет ровно 5 раз равна 0,5 | M7: Среди предложенных выше ответов нет верного | N7: 54 | O7: Моды у данного распределения нет, Количество билетов, проданное в декабре представленного года более чем в 1,5 раза меньше, чем количество билетов, проданное в декабре предыдущего года | P7: Непропорциональное масштабирование, Для представления данных такой тип визуализации не подходит | Q7: 42 | R7: Медиана прибылей за рассматриваемые четыре месяца | S7: 219 | T7: Мода роста выборки из всех участников коллектива равна 58 см. | U7: Не должна меняться | V7: 1 | W7: только (1) | X7: 5, 4,8 | Y7: Исходя из двух графиков, можно сделать вывод о том, что в Японии в среднем случается больше ДТП, чем в России, Исходя из данных графиков, Австралия - самая безопасная страна для автовождения из представленных, Показатель летальных исходов в России наиболее меняющийся | Z7: Выборка, составленная по Японии, содержит одну моду - 9.20 | AA7: В развитых странах ситуация с трудоустройством иностранных резидентов, в целом, обстоит лучше, нежели в развивающихся, Самый высокий показатель трудоустройства не означает того, что в Исландии самая большая доля трудоспособного иностранного населения по сравнению с другими странами, Размах выборки составляет примерно 0,35 | AB7: И по результатам оценки уровня читательской грамотности, и по результатам оценки уровня математической грамотности наблюдается определенный лидер - в данном случае это девочки и мальчики соответственно, В обоих случаях баллы российских участников находятся левее среднего арифметического баллов по анализируемым странам, Результаты российских участников примерно на 10 процентных пункта меньше среднего уровня читательской грамотности | AC7: Данное распределение - одномодальное | AD7: 3, 17 | AE7: Если предположить, что всего было зафиксировано 30 наблюдений, то выборку, представляющую собой объединение 4-х выборок, представленных выше, точно можно назвать более репрезентативной, чем каждую из вышеупомянутых выборок по отдельности
A8: 44363.861 | B8: kirikdolk@mail.ru | C8: 9 | D8: 93b071d7-8fd2-426e-baf2-13e85bb9d015 | E8: 9 | F8: 10, 6,25, 0 | G8: Уменьшится | H8: Медианное количество детей в семье - 2 ребенка, Среднее количество детей в семье меньше медианного, В городе N родителей больше, чем детей, При сохранении данных статистических показателей в городе N на протяжении длительного времени, можно будет говорить об отрицательном естественном приросте населения | I8: В среднем в регионах воздерживаются от ответа менее 4,5% опрошенных, Среднее значение опрошенных, поддерживающих кандидата А, в регионах 1, 2 и 4 равно 63,8% | J8: 64 | K8: Из-за увеличения урожайности зерна планируется, что дисперсия по десятилетней выборке увеличится и станет равна 201,16, Средняя будет равна 39,2, Дисперсия не изменится | L8: Вероятность того, что орел выпадет ровно 9 раз меньше одного процента | M8: Среди предложенных выше ответов нет верного | N8: 56 | O8: Квартиль 1-го порядка равен 104 | P8: Непропорциональное масштабирование, Использование процентов вместо абсолютных величин | Q8: 30 | R8: Медиана прибылей за рассматриваемые четыре месяца | S8: 220 | T8: Размах выборки, состоящей из показателей роста участников, чей вес не превышает 58 кг, равен 0,22 м., Данный тип диаграммы называется диаграммой рассеивания, Вес бóльшей части девочек превышает средний вес мальчиков | U8: Приблизительно на 3% | V8: 3 | W8: только (3) | X8: 4,4, 5,6 | Y8: В Японии разброс значений количества летальных исходов в целом ниже, нежели разброс в России, Исходя из данных графиков, Австралия - самая безопасная страна для автовождения из представленных, Разрыв по количеству летальных исходов в ДТП между США и Россией продолжает расти, Показатель летальных исходов в России наиболее меняющийся | Z8: Великобритания - лидер по количеству выбросов | AA8: Исландия - самая привлекательная страна для мигрантов, Самый высокий показатель трудоустройства не означает того, что в Исландии самая большая доля трудоспособного иностранного населения по сравнению с другими странами, Среднее значение уровня вовлеченности в рабочую силу в группе среди 5 лидеров примерно на 25% выше, нежели среднее в группе среди 5 аутсайдеров | AB8: Разброс результатов тестирования между полами сильнее при исследовании уровня читательской грамотности, нежели математической, В обоих случаях баллы российских участников находятся левее среднего арифметического баллов по анализируемым странам, Результаты российских участников примерно на 10 процентных пункта меньше среднего уровня читательской грамотности | AC8: Третий квартиль равен 11 | AD8: 13, 7 | AE8: Линейная линия тренда выборки, представляющей собой объединение четырёх вышеупомянутых выборок, будет иметь положительный коэффициент наклона, который будет иметь значение между коэффициентом наклона первой выборки и четвёртой
A9: 44363.904 | B9: onchaev@mail.ru | C9: 4 | D9: 93b084b6-71d4-40a9-8180-f0634e673cf5 | E9: 9 | G9: Уменьшится | H9: Медианное количество детей в семье - 2 ребенка, Среднее количество детей в семье меньше медианного, В городе N родителей больше, чем детей | I9: Более половины опрошенных поддерживает кандидата А, Среднее значение опрошенных, поддерживающих кандидата А, в регионах 1, 2 и 4 равно 63,8% | K9: Средняя будет равна 39,2, Дисперсия не изменится | L9: Вероятность того, что орел выпадет ровно 9 раз меньше одного процента, Вероятность того, что орел выпадет более 5 раз выше, чем вероятность того, что он выпадет меньше пяти раз | M9: Среди предложенных выше ответов нет верного | N9: 56 | O9: Моды у данного распределения нет, Количество билетов, проданное в декабре представленного года более чем в 1,5 раза меньше, чем количество билетов, проданное в декабре предыдущего года | P9: Непропорциональное масштабирование, Для представления данных такой тип визуализации не подходит | Q9: 30 | R9: Среднее значение прибылей за рассматриваемые четыре месяца, Медиана прибылей за рассматриваемые четыре месяца | S9: 220 | T9: Мода роста выборки из всех участников коллектива равна 58 см., Данный тип диаграммы называется диаграммой рассеивания, Вес бóльшей части девочек превышает средний вес мальчиков | U9: Приблизительно на 2%
A10: 44363.937 | B10: a.osipenkov2004@gmail.com | C10: 8 | D10: 93b09b91-0d5b-4ae8-8bd0-46286901f288 | E10: 11 | F10: 10, 6,25, 0 | G10: Уменьшится | H10: Медианное количество детей в семье - 2 ребенка, Среднее количество детей в семье меньше медианного, В городе N родителей больше, чем детей, При сохранении данных статистических показателей в городе N на протяжении длительного времени, можно будет говорить об отрицательном естественном приросте населения | I10: Медианное значение опрошенных, поддерживающих кандидата В, в регионах равно 41,1%, Среднее значение опрошенных, поддерживающих кандидата А, в регионах 1, 2 и 4 равно 63,8% | J10: 64 | K10: Из-за увеличения урожайности зерна планируется, что дисперсия по десятилетней выборке увеличится и станет равна 201,16, Средняя будет равна 39,2 | L10: Вероятность того, что орел выпадет ровно 9 раз меньше одного процента, Вероятность того, что орел выпадет 4 раза не равна вероятности выпадения орла 6 раз | M10: Среди предложенных выше ответов нет верного | N10: Недостаточно информации, чтобы определить | O10: Медиана располагается в промежутке [86;95], Количество билетов, проданное в декабре представленного года более чем в 1,5 раза меньше, чем количество билетов, проданное в декабре предыдущего года | P10: Использование процентов вместо абсолютных величин, Для представления данных такой тип визуализации не подходит | Q10: 42 | R10: Среднее значение прибылей за рассматриваемые четыре месяца, Дисперсия прибылей за рассматриваемые четыре месяца, Стандартное отклонение прибылей за рассматриваемые четыре месяца | S10: 228 | T10: Мода роста выборки из всех участников коллектива равна 58 см., Данный тип диаграммы называется диаграммой рассеивания, Вес бóльшей части девочек превышает средний вес мальчиков, Если в коллектив придет девочка весом в 54 кг, то медианный вес девочек не изменится | U10: Среди предложенных вариантов нет верного | V10: 5 | W10: только (3) | X10: 5, 5,2 | Y10: В Японии разброс значений количества летальных исходов в целом ниже, нежели разброс в России, Разрыв по количеству летальных исходов в ДТП между США и Россией продолжает расти, Показатель летальных исходов в России наиболее меняющийся | Z10: В США наблюдается тренд на снижение количества выбросов парниковых газов на человека | AA10: Исландия - самая привлекательная страна для мигрантов, Самый высокий показатель трудоустройства не означает того, что в Исландии самая большая доля трудоспособного иностранного населения по сравнению с другими странами, Размах выборки составляет примерно 0,35 | AB10: И по результатам оценки уровня читательской грамотности, и по результатам оценки уровня математической грамотности наблюдается определенный лидер - в данном случае это девочки и мальчики соответственно, Разброс результатов тестирования между полами сильнее при исследовании уровня читательской грамотности, нежели математической, В обоих случаях баллы российских участников находятся левее среднего арифметического баллов по анализируемым странам, Результаты российских участников примерно на 10 процентных пункта меньше среднего уровня читательской грамотности | AC10: Третий квартиль равен 11 | AD10: 5, 15 | AE10: Линейная линия тренда выборки, представляющей собой объединение четырёх вышеупомянутых выборок, будет иметь положительный коэффициент наклона, который будет иметь значение между коэффициентом наклона первой выборки и четвёртой
A11: 44364.33 | B11: sschirkova76@yandex.ru | C11: 12 | D11: 93b16008-b5ed-4581-9fbd-efc8afd1dea1 | E11: 10 | F11: 0, 6,25, 9 | G11: Уменьшится | H11: Медианное количество детей в семье - 2 ребенка, Среднее количество детей в семье меньше медианного, В городе N родителей больше, чем детей, При сохранении данных статистических показателей в городе N на протяжении длительного времени, можно будет говорить об отрицательном естественном приросте населения | I11: Среднее значение опрошенных, поддерживающих кандидата А, в регионах 1, 2 и 4 равно 63,8% | J11: 64 | K11: Средняя будет равна 39,2, Дисперсия не изменится | L11: Вероятность того, что орел выпадет ровно 5 раз равна 0,5 | M11: Среди предложенных выше ответов нет верного | N11: 56 | O11: Количество билетов, проданное в декабре представленного года более чем в 1,5 раза меньше, чем количество билетов, проданное в декабре предыдущего года | P11: Непропорциональное масштабирование, Использование процентов вместо абсолютных величин, Для представления данных такой тип визуализации не подходит | Q11: Среди предложенных нет верного ответа | R11: Среднее значение прибылей за рассматриваемые четыре месяца | S11: 228 | T11: Данный тип диаграммы называется диаграммой рассеивания, Если в коллектив придет девочка весом в 54 кг, то медианный вес девочек не изменится | U11: Приблизительно на 2% | V11: 1 | W11: только (3) | X11: 5, 5,2 | Y11: В Японии разброс значений количества летальных исходов в целом ниже, нежели разброс в России, Разрыв по количеству летальных исходов в ДТП между США и Россией продолжает расти, Показатель летальных исходов в России наиболее меняющийся | Z11: В США наблюдается тренд на снижение количества выбросов парниковых газов на человека | AA11: Самый высокий показатель трудоустройства не означает того, что в Исландии самая большая доля трудоспособного иностранного населения по сравнению с другими странами | AB11: И по результатам оценки уровня читательской грамотности, и по результатам оценки уровня математической грамотности наблюдается определенный лидер - в данном случае это девочки и мальчики соответственно | AC11: Данное распределение - одномодальное | AD11: 13, 7 | AE11: Если предположить, что всего было зафиксировано 30 наблюдений, то выборку, представляющую собой объединение 4-х выборок, представленных выше, точно можно назвать более репрезентативной, чем каждую из вышеупомянутых выборок по отдельности
A12: 44364.389 | B12: klimkina.15012004@gmail.com | C12: 5 | D12: 93b19dbe-0fad-4709-87d5-60f513782a87 | E12: 11 | F12: 0, 6,25, 9 | G12: Уменьшится | H12: Мода числа детей в семье равняется 3, При сохранении данных статистических показателей в городе N на протяжении длительного времени, можно будет говорить об отрицательном естественном приросте населения | I12: Более половины опрошенных поддерживает кандидата А, Среднее значение опрошенных, поддерживающих кандидата А, в регионах 1, 2 и 4 равно 63,8% | J12: 32 | K12: Средняя будет равна 39,2, Невозможно определить изменение дисперсии, так как не хватает данных сразу по двум годам. | L12: Вероятность того, что орел выпадет ровно 9 раз меньше одного процента, Вероятность того, что орел выпадет 4 раза не равна вероятности выпадения орла 6 раз | M12: Цена билета равна 364 руб. | N12: 58 | O12: Генеральная дисперсия равна 2092,45, Моды у данного распределения нет | P12: Использование процентов вместо абсолютных величин | Q12: 42 | R12: Среднее значение прибылей за рассматриваемые четыре месяца, Стандартное отклонение прибылей за рассматриваемые четыре месяца | S12: 225 | T12: Данный тип диаграммы называется диаграммой рассеивания, Вес бóльшей части девочек превышает средний вес мальчиков | U12: Приблизительно на 1% | V12: 3 | W12: только (3) | X12: 5.6 | Y12: Исходя из данных графиков, Австралия - самая безопасная страна для автовождения из представленных, Показатель летальных исходов в России наиболее меняющийся | Z12: Великобритания - лидер по количеству выбросов | AA12: Самый высокий показатель трудоустройства не означает того, что в Исландии самая большая доля трудоспособного иностранного населения по сравнению с другими странами | AB12: В обоих случаях баллы российских участников находятся левее среднего арифметического баллов по анализируемым странам, Результаты российских участников примерно на 10 процентных пункта меньше среднего уровня читательской грамотности | AC12: Медиана равна 5 | AD12: 10, 10 | AE12: Коэффициент корреляции Пирсона будет иметь больше значение в случае с объединённой выборкой из первой и четвёртой выборками, чем аналогичный коэффициент Пирсона выборки, состоящей из второй и третьей выборок
A13: 44364.569 | B13: ExtrimHack1@mail.ru | C13: 5 | D13: 93b1f2d4-5c9d-4ba3-a196-9625a561e6eb | E13: 11 | F13: 10, 6,25, 0 | G13: Уменьшится | H13: Медианное количество детей в семье - 2 ребенка, Среднее количество детей в семье меньше медианного, При сохранении данных статистических показателей в городе N на протяжении длительного времени, можно будет говорить об отрицательном естественном приросте населения | I13: В среднем в регионах воздерживаются от ответа менее 4,5% опрошенных, Более половины опрошенных поддерживает кандидата А | J13: 16 | K13: Средняя будет равна 39,2 | L13: Вероятность того, что орел выпадет ровно 5 раз равна 0,5 | M13: Цена билета равна 364 руб. | N13: 58 | O13: Медиана располагается в промежутке [86;95] | P13: Непропорциональное масштабирование | Q13: 30 | R13: Медиана прибылей за рассматриваемые четыре месяца | S13: 220 | T13: Мода роста выборки из всех участников коллектива равна 58 см. | U13: Приблизительно на 1% | V13: 2 | W13: только (1) и (2) | X13: 5.2 | Y13: Разрыв по количеству летальных исходов в ДТП между США и Россией продолжает расти | Z13: Выборка, составленная по Японии, содержит одну моду - 9.20 | AA13: Самый высокий показатель трудоустройства не означает того, что в Исландии самая большая доля трудоспособного иностранного населения по сравнению с другими странами | AB13: Уровень читательской грамотности у детей из стран Азии в целом ниже, нежели у детей | AC13: Третий квартиль равен 11 | AD13: 10, 10 | AE13: Выборка, состоящая из 2-х наблюдений, не может быть репрезентативной
A14: 44364.659 | B14: filippglumov@gmail.com | C14: 9 | D14: 93b20442-f1e4-4e6a-9ce1-bbfa2dedd1e0 | E14: 11 | F14: 10, 6,25, 0 | G14: Уменьшится | H14: Медианное количество детей в семье - 2 ребенка, Среднее количество детей в семье меньше медианного, В городе N родителей больше, чем детей, При сохранении данных статистических показателей в городе N на протяжении длительного времени, можно будет говорить об отрицательном естественном приросте населения | I14: Среднее значение опрошенных, поддерживающих кандидата А, в регионах 1, 2 и 4 равно 63,8% | J14: 4 | K14: Невозможно определить изменение дисперсии, так как не хватает данных сразу по двум годам. | L14: Вероятность того, что орел выпадет ровно 9 раз меньше одного процента | M14: Среди предложенных выше ответов нет верного | N14: Недостаточно информации, чтобы определить | O14: Моды у данного распределения нет | P14: Непропорциональное масштабирование | Q14: 42 | R14: Среднее значение прибылей за рассматриваемые четыре месяца | S14: 228 | T14: Вес бóльшей части девочек превышает средний вес мальчиков, Если в коллектив придет девочка весом в 54 кг, то медианный вес девочек не изменится
A15: 44365.463 | B15: loamelina@edu.hse.ru | C15: 5 | D15: 93b3c663-b5db-40b4-b0a1-d04d146a6b6e | E15: Студент/студентка | F15: 10, 6,25, 0 | G15: Не уменьшится | H15: Среднее количество детей в семье меньше медианного, При сохранении данных статистических показателей в городе N на протяжении длительного времени, можно будет говорить об отрицательном естественном приросте населения | I15: Более половины опрошенных поддерживает кандидата А, Если бы все воздержавшиеся от ответа поддержали бы кандидата Б, то он точно бы имел большее количество поддерживающих его опрошенных, нежили А | J15: 16 | K15: Из-за увеличения урожайности зерна планируется, что дисперсия по десятилетней выборке увеличится и станет равна 201,16, Невозможно определить изменение дисперсии, так как не хватает данных сразу по двум годам. | L15: Вероятность того, что орел выпадет более 5 раз выше, чем вероятность того, что он выпадет меньше пяти раз, Вероятность того, что орел выпадет ровно 3 раза больше 0,2 | M15: Цена билета равна 330 руб. | N15: 56 | O15: Моды у данного распределения нет, Количество билетов, проданное в декабре представленного года более чем в 1,5 раза меньше, чем количество билетов, проданное в декабре предыдущего года | P15: Непропорциональное масштабирование, Для представления данных такой тип визуализации не подходит | Q15: 46 | R15: Медиана прибылей за рассматриваемые четыре месяца, Дисперсия прибылей за рассматриваемые четыре месяца | S15: 219 | T15: Мода роста выборки из всех участников коллектива равна 58 см., Если в коллектив придет девочка весом в 54 кг, то медианный вес девочек не изменится | U15: Не должна меняться | V15: 2 | W15: только (2) и (3) | X15: 4.8 | Y15: Исходя из двух графиков, можно сделать вывод о том, что в Японии в среднем случается больше ДТП, чем в России, Исходя из данных графиков, Австралия - самая безопасная страна для автовождения из представленных | Z15: Медианное значение выбросов в Великобритании в период с 2001 по 2011 включительно составляет 8.80 | AA15: Самый высокий показатель трудоустройства не означает того, что в Исландии самая большая доля трудоспособного иностранного населения по сравнению с другими странами, Среднее значение уровня вовлеченности в рабочую силу в группе среди 5 лидеров примерно на 25% выше, нежели среднее в группе среди 5 аутсайдеров | AB15: И по результатам оценки уровня читательской грамотности, и по результатам оценки уровня математической грамотности наблюдается определенный лидер - в данном случае это девочки и мальчики соответственно, В обоих случаях баллы российских участников находятся левее среднего арифметического баллов по анализируемым странам | AC15: Третий квартиль равен 11 | AD15: 10, 10 | AE15: Линейная линия тренда выборки, представляющей собой объединение четырёх вышеупомянутых выборок, будет иметь положительный коэффициент наклона, который будет иметь значение между коэффициентом наклона первой выборки и четвёртой
A16: 44365.502 | B16: myubelozerov@edu.hse.ru | C16: 11 | D16: 93b3c86b-9ff8-434e-ae1f-8c4b3eddaba6 | E16: Студент/студентка | F16: 10, 6,25, 0 | G16: Уменьшится | H16: Медианное количество детей в семье - 2 ребенка, В городе N родителей больше, чем детей, При сохранении данных статистических показателей в городе N на протяжении длительного времени, можно будет говорить об отрицательном естественном приросте населения | I16: Среднее значение опрошенных, поддерживающих кандидата А, в регионах 1, 2 и 4 равно 63,8% | J16: 32 | K16: Средняя будет равна 39,2, Дисперсия не изменится | L16: Вероятность того, что орел выпадет ровно 9 раз меньше одного процента, Вероятность того, что орел выпадет более 5 раз выше, чем вероятность того, что он выпадет меньше пяти раз | M16: Среди предложенных выше ответов нет верного | N16: Недостаточно информации, чтобы определить | O16: Медиана располагается в промежутке [86;95], Моды у данного распределения нет | P16: Непропорциональное масштабирование, Использование процентов вместо абсолютных величин, Для представления данных такой тип визуализации не подходит | Q16: 42 | R16: Среднее значение прибылей за рассматриваемые четыре месяца, Дисперсия прибылей за рассматриваемые четыре месяца | S16: 228 | T16: Если в коллектив придет девочка весом в 54 кг, то медианный вес девочек не изменится | U16: Приблизительно на 1% | V16: 1 | W16: только (3) | X16: 5, 5,2 | Y16: Исходя из двух графиков, можно сделать вывод о том, что в Японии в среднем случается больше ДТП, чем в России, В Японии разброс значений количества летальных исходов в целом ниже, нежели разброс в России, Исходя из данных графиков, Австралия - самая безопасная страна для автовождения из представленных, Показатель летальных исходов в России наиболее меняющийся | Z16: В США наблюдается тренд на снижение количества выбросов парниковых газов на человека | AA16: Исландия - самая привлекательная страна для мигрантов, Самый высокий показатель трудоустройства не означает того, что в Исландии самая большая доля трудоспособного иностранного населения по сравнению с другими странами, Среднее значение уровня вовлеченности в рабочую силу в группе среди 5 лидеров примерно на 25% выше, нежели среднее в группе среди 5 аутсайдеров | AB16: И по результатам оценки уровня читательской грамотности, и по результатам оценки уровня математической грамотности наблюдается определенный лидер - в данном случае это девочки и мальчики соответственно, Разброс результатов тестирования между полами сильнее при исследовании уровня читательской грамотности, нежели математической, В обоих случаях баллы российских участников находятся левее среднего арифметического баллов по анализируемым странам, Результаты российских участников примерно на 10 процентных пункта меньше среднего уровня читательской грамотности | AC16: Данное распределение - одномодальное | AD16: 3, 17 | AE16: Выборка, состоящая из 2-х наблюдений, не может быть репрезентативной
A17: 44365.74 | B17: nosmasha@gmail.com | C17: 4 | D17: 93b43249-eda2-490f-895b-499edda23039 | E17: Студент/студентка | F17: 10, 6,25, 0 | G17: Уменьшится | H17: Среднее количество детей в семье меньше медианного, В городе N родителей больше, чем детей | I17: Более половины опрошенных поддерживает кандидата А, Медианное значение опрошенных, поддерживающих кандидата В, в регионах равно 41,1%, Среднее значение опрошенных, поддерживающих кандидата А, в регионах 1, 2 и 4 равно 63,8% | J17: 32 | K17: Средняя будет равна 39,2, Дисперсия не изменится | L17: Вероятность того, что орел выпадет более 5 раз выше, чем вероятность того, что он выпадет меньше пяти раз, Вероятность того, что орел выпадет ровно 3 раза больше 0,2 | M17: Цена билета равна 364 руб. | N17: Недостаточно информации, чтобы определить | O17: Квартиль 1-го порядка равен 104, Моды у данного распределения нет | P17: Для представления данных такой тип визуализации не подходит | Q17: 46
A19: 44367.527 | B19: m.stolyaroff2014@yandex.ru | C19: 25 | D19: 93b7edac-675a-4a66-a4d6-597ec0b56279 | E19: Студент/студентка | F19: 10, 6,25, 0 | G19: Уменьшится | H19: Медианное количество детей в семье - 2 ребенка, Среднее количество детей в семье меньше медианного, В городе N родителей больше, чем детей, При сохранении данных статистических показателей в городе N на протяжении длительного времени, можно будет говорить об отрицательном естественном приросте населения | I19: Среднее значение опрошенных, поддерживающих кандидата А, в регионах 1, 2 и 4 равно 63,8% | J19: 32 | K19: Средняя будет равна 39,2, Дисперсия не изменится | L19: Вероятность того, что орел выпадет ровно 9 раз меньше одного процента | M19: Среди предложенных выше ответов нет верного | N19: 56 | O19: Медиана располагается в промежутке [86;95], Моды у данного распределения нет, Количество билетов, проданное в декабре представленного года более чем в 1,5 раза меньше, чем количество билетов, проданное в декабре предыдущего года | P19: Сдвиг шкалы, Непропорциональное масштабирование, Использование процентов вместо абсолютных величин | Q19: 42 | R19: Среднее значение прибылей за рассматриваемые четыре месяца | S19: 228 | T19: Данный тип диаграммы называется диаграммой рассеивания, Если в коллектив придет девочка весом в 54 кг, то медианный вес девочек не изменится | U19: Приблизительно на 1% | V19: 1 | W19: только (3) | X19: 5, 5,2 | Y19: Исходя из двух графиков, можно сделать вывод о том, что в Японии в среднем случается больше ДТП, чем в России, Исходя из данных графиков, Австралия - самая безопасная страна для автовождения из представленных, Разрыв по количеству летальных исходов в ДТП между США и Россией продолжает расти | Z19: Медианное значение выбросов в Великобритании в период с 2001 по 2011 включительно составляет 8.80 | AA19: В развитых странах ситуация с трудоустройством иностранных резидентов, в целом, обстоит лучше, нежели в развивающихся, Самый высокий показатель трудоустройства не означает того, что в Исландии самая большая доля трудоспособного иностранного населения по сравнению с другими странами, Среднее значение уровня вовлеченности в рабочую силу в группе среди 5 лидеров примерно на 25% выше, нежели среднее в группе среди 5 аутсайдеров | AB19: Разброс результатов тестирования между полами сильнее при исследовании уровня читательской грамотности, нежели математической, В обоих случаях баллы российских участников находятся левее среднего арифметического баллов по анализируемым странам | AC19: Третий квартиль равен 11 | AD19: 13, 7 | AE19: Нет верных утверждений

Sheet Баллы
A1: Правильный ответ: | D1: 10, 6,25, 0 | E1: Уменьшится | F1: Медианное количество детей в семье - 2 ребенка, Среднее количество детей в семье меньше медианного, В городе N родителей больше, чем детей, При сохранении данных статистических показателей в городе N на протяжении длительного времени, можно будет говорить об отрицательном естественном приросте населения | G1: Среднее значение опрошенных, поддерживающих кандидата А, в регионах 1, 2 и 4 равно 63,8% | H1: 32 | I1: Средняя будет равна 39,2, Дисперсия не изменится | J1: Вероятность того, что орел выпадет ровно 9 раз меньше одного процента | K1: Среди предложенных выше ответов нет верного | L1: 56 | M1: Медиана располагается в промежутке [86;95], Моды у данного распределения нет, Количество билетов, проданное в декабре представленного года более чем в 1,5 раза меньше, чем количество билетов, проданное в декабре предыдущего года | N1: Сдвиг шкалы, Непропорциональное масштабирование, Использование процентов вместо абсолютных величин | O1: 42 | P1: Среднее значение прибылей за рассматриваемые четыре месяца | Q1: 228 | R1: Данный тип диаграммы называется диаграммой рассеивания, Если в коллектив придет девочка весом в 54 кг, то медианный вес девочек не изменится | S1: Приблизительно на 1% | T1: 1 | U1: только (3) | V1: 5, 5,2 | W1: Исходя из двух графиков, можно сделать вывод о том, что в Японии в среднем случается больше ДТП, чем в России, Исходя из данных графиков, Австралия - самая безопасная страна для автовождения из представленных, Разрыв по количеству летальных исходов в ДТП между США и Россией продолжает расти | X1: Медианное значение выбросов в Великобритании в период с 2001 по 2011 включительно составляет 8.80 | Y1: В развитых странах ситуация с трудоустройством иностранных резидентов, в целом, обстоит лучше, нежели в развивающихся, Самый высокий показатель трудоустройства не означает того, что в Исландии самая большая доля трудоспособного иностранного населения по сравнению с другими странами, Среднее значение уровня вовлеченности в рабочую силу в группе среди 5 лидеров примерно на 25% выше, нежели среднее в группе среди 5 аутсайдеров | Z1: Разброс результатов тестирования между полами сильнее при исследовании уровня читательской грамотности, нежели математической, В обоих случаях баллы российских участников находятся левее среднего арифметического баллов по анализируемым странам | AA1: Третий квартиль равен 11 | AB1: 13, 7 | AC1: Нет верных утверждений
A2: Время: | B2: Испытуемый: | C2: Сумма баллов: | D2: 1 | E2: 2 | F2: 3 | G2: 4 | H2: 5 | I2: 6 | J2: 7 | K2: 8 | L2: 9 | M2: 10 | N2: 11 | O2: 12 | P2: 13 | Q2: 14 | R2: 15 | S2: 16 | T2: 17 | U2: 18 | V2: 19 | W2: 20 | X2: 21 | Y2: 22 | Z2: 23 | AA2: 24 | AB2: 25 | AC2: 26
A3: ='Ответы на форму (1)'!A2 -> 44359.972 | B3: ='Ответы на форму (1)'!B2 -> micro.fascinated@gmail.com | C3: =SUM(D3:AC3) -> 17 | D3: =IF('Ответы на форму (1)'!F2=D$1 ,1, 0) -> 1 | E3: =IF('Ответы на форму (1)'!G2=E$1 ,1, 0) -> 0 | F3: =IF('Ответы на форму (1)'!H2=F$1 ,1, 0) -> 0 | G3: =IF('Ответы на форму (1)'!I2=G$1 ,1, 0) -> 0 | H3: =IF('Ответы на форму (1)'!J2=H$1 ,1, 0) -> 1 | I3: =IF('Ответы на форму (1)'!K2=I$1 ,1, 0) -> 0 | J3: =IF('Ответы на форму (1)'!L2=J$1 ,1, 0) -> 0 | K3: =IF('Ответы на форму (1)'!M2=K$1 ,1, 0) -> 0 | ... AC3: =IF('Ответы на форму (1)'!AE2=AC$1 ,1, 0) -> 1
A4: ='Ответы на форму (1)'!A3 -> 44362.945 | B4: ='Ответы на форму (1)'!B3 -> egorpranikov39562@gmail.com | C4: =SUM(D4:AC4) -> 0 | D4: =IF('Ответы на форму (1)'!F3=D$1 ,1, 0) -> 0 | E4: =IF('Ответы на форму (1)'!G3=E$1 ,1, 0) -> 0 | F4: =IF('Ответы на форму (1)'!H3=F$1 ,1, 0) -> 0 | G4: =IF('Ответы на форму (1)'!I3=G$1 ,1, 0) -> 0 | H4: =IF('Ответы на форму (1)'!J3=H$1 ,1, 0) -> 0 | I4: =IF('Ответы на форму (1)'!K3=I$1 ,1, 0) -> 0 | J4: =IF('Ответы на форму (1)'!L3=J$1 ,1, 0) -> 0 | K4: =IF('Ответы на форму (1)'!M3=K$1 ,1, 0) -> 0 | ... AC4: =IF('Ответы на форму (1)'!AE3=AC$1 ,1, 0) -> 0
A5: ='Ответы на форму (1)'!A4 -> 44363.731 | B5: ='Ответы на форму (1)'!B4 -> utygo@mail.ru | C5: =SUM(D5:AC5) -> 3 | D5: =IF('Ответы на форму (1)'!F4=D$1 ,1, 0) -> 0 | E5: =IF('Ответы на форму (1)'!G4=E$1 ,1, 0) -> 0 | F5: =IF('Ответы на форму (1)'!H4=F$1 ,1, 0) -> 0 | G5: =IF('Ответы на форму (1)'!I4=G$1 ,1, 0) -> 0 | H5: =IF('Ответы на форму (1)'!J4=H$1 ,1, 0) -> 1 | I5: =IF('Ответы на форму (1)'!K4=I$1 ,1, 0) -> 0 | J5: =IF('Ответы на форму (1)'!L4=J$1 ,1, 0) -> 0 | K5: =IF('Ответы на форму (1)'!M4=K$1 ,1, 0) -> 0 | ... AC5: =IF('Ответы на форму (1)'!AE4=AC$1 ,1, 0) -> 0
A6: ='Ответы на форму (1)'!A5 -> 44363.753 | B6: ='Ответы на форму (1)'!B5 -> danya.palatkin@yandex.ru | C6: =SUM(D6:AC6) -> 3 | D6: =IF('Ответы на форму (1)'!F5=D$1 ,1, 0) -> 0 | E6: =IF('Ответы на форму (1)'!G5=E$1 ,1, 0) -> 0 | F6: =IF('Ответы на форму (1)'!H5=F$1 ,1, 0) -> 0 | G6: =IF('Ответы на форму (1)'!I5=G$1 ,1, 0) -> 0 | H6: =IF('Ответы на форму (1)'!J5=H$1 ,1, 0) -> 0 | I6: =IF('Ответы на форму (1)'!K5=I$1 ,1, 0) -> 0 | J6: =IF('Ответы на форму (1)'!L5=J$1 ,1, 0) -> 0 | K6: =IF('Ответы на форму (1)'!M5=K$1 ,1, 0) -> 0 | ... AC6: =IF('Ответы на форму (1)'!AE5=AC$1 ,1, 0) -> 0
A7: ='Ответы на форму (1)'!A6 -> 44363.816 | B7: ='Ответы на форму (1)'!B6 -> catya.mentyukova@yandex.ru | C7: =SUM(D7:AC7) -> 21 | D7: =IF('Ответы на форму (1)'!F6=D$1 ,1, 0) -> 1 | E7: =IF('Ответы на форму (1)'!G6=E$1 ,1, 0) -> 1 | F7: =IF('Ответы на форму (1)'!H6=F$1 ,1, 0) -> 0 | G7: =IF('Ответы на форму (1)'!I6=G$1 ,1, 0) -> 1 | H7: =IF('Ответы на форму (1)'!J6=H$1 ,1, 0) -> 0 | I7: =IF('Ответы на форму (1)'!K6=I$1 ,1, 0) -> 1 | J7: =IF('Ответы на форму (1)'!L6=J$1 ,1, 0) -> 1 | K7: =IF('Ответы на форму (1)'!M6=K$1 ,1, 0) -> 1 | ... AC7: =IF('Ответы на форму (1)'!AE6=AC$1 ,1, 0) -> 1
A8: ='Ответы на форму (1)'!A7 -> 44363.823 | B8: ='Ответы на форму (1)'!B7 -> atremy.rybkin@gmail.com | C8: =SUM(D8:AC8) -> 6 | D8: =IF('Ответы на форму (1)'!F7=D$1 ,1, 0) -> 1 | E8: =IF('Ответы на форму (1)'!G7=E$1 ,1, 0) -> 1 | F8: =IF('Ответы на форму (1)'!H7=F$1 ,1, 0) -> 1 | G8: =IF('Ответы на форму (1)'!I7=G$1 ,1, 0) -> 0 | H8: =IF('Ответы на форму (1)'!J7=H$1 ,1, 0) -> 0 | I8: =IF('Ответы на форму (1)'!K7=I$1 ,1, 0) -> 0 | J8: =IF('Ответы на форму (1)'!L7=J$1 ,1, 0) -> 0 | K8: =IF('Ответы на форму (1)'!M7=K$1 ,1, 0) -> 1 | ... AC8: =IF('Ответы на форму (1)'!AE7=AC$1 ,1, 0) -> 0
A9: ='Ответы на форму (1)'!A8 -> 44363.861 | B9: ='Ответы на форму (1)'!B8 -> kirikdolk@mail.ru | C9: =SUM(D9:AC9) -> 9 | D9: =IF('Ответы на форму (1)'!F8=D$1 ,1, 0) -> 1 | E9: =IF('Ответы на форму (1)'!G8=E$1 ,1, 0) -> 1 | F9: =IF('Ответы на форму (1)'!H8=F$1 ,1, 0) -> 1 | G9: =IF('Ответы на форму (1)'!I8=G$1 ,1, 0) -> 0 | H9: =IF('Ответы на форму (1)'!J8=H$1 ,1, 0) -> 0 | I9: =IF('Ответы на форму (1)'!K8=I$1 ,1, 0) -> 0 | J9: =IF('Ответы на форму (1)'!L8=J$1 ,1, 0) -> 1 | K9: =IF('Ответы на форму (1)'!M8=K$1 ,1, 0) -> 1 | ... AC9: =IF('Ответы на форму (1)'!AE8=AC$1 ,1, 0) -> 0
A10: ='Ответы на форму (1)'!A9 -> 44363.904 | B10: ='Ответы на форму (1)'!B9 -> onchaev@mail.ru | C10: =SUM(D10:AC10) -> 4 | D10: =IF('Ответы на форму (1)'!F9=D$1 ,1, 0) -> 0 | E10: =IF('Ответы на форму (1)'!G9=E$1 ,1, 0) -> 1 | F10: =IF('Ответы на форму (1)'!H9=F$1 ,1, 0) -> 0 | G10: =IF('Ответы на форму (1)'!I9=G$1 ,1, 0) -> 0 | H10: =IF('Ответы на форму (1)'!J9=H$1 ,1, 0) -> 0 | I10: =IF('Ответы на форму (1)'!K9=I$1 ,1, 0) -> 1 | J10: =IF('Ответы на форму (1)'!L9=J$1 ,1, 0) -> 0 | K10: =IF('Ответы на форму (1)'!M9=K$1 ,1, 0) -> 1 | ... AC10: =IF('Ответы на форму (1)'!AE9=AC$1 ,1, 0) -> 0
A11: ='Ответы на форму (1)'!A10 -> 44363.937 | B11: ='Ответы на форму (1)'!B10 -> a.osipenkov2004@gmail.com | C11: =SUM(D11:AC11) -> 9 | D11: =IF('Ответы на форму (1)'!F10=D$1 ,1, 0) -> 1 | E11: =IF('Ответы на форму (1)'!G10=E$1 ,1, 0) -> 1 | F11: =IF('Ответы на форму (1)'!H10=F$1 ,1, 0) -> 1 | G11: =IF('Ответы на форму (1)'!I10=G$1 ,1, 0) -> 0 | H11: =IF('Ответы на форму (1)'!J10=H$1 ,1, 0) -> 0 | I11: =IF('Ответы на форму (1)'!K10=I$1 ,1, 0) -> 0 | J11: =IF('Ответы на форму (1)'!L10=J$1 ,1, 0) -> 0 | K11: =IF('Ответы на форму (1)'!M10=K$1 ,1, 0) -> 1 | ... AC11: =IF('Ответы на форму (1)'!AE10=AC$1 ,1, 0) -> 0
A12: ='Ответы на форму (1)'!A11 -> 44364.33 | B12: ='Ответы на форму (1)'!B11 -> sschirkova76@yandex.ru | C12: =SUM(D12:AC12) -> 13 | D12: =IF('Ответы на форму (1)'!F11=D$1 ,1, 0) -> 0 | E12: =IF('Ответы на форму (1)'!G11=E$1 ,1, 0) -> 1 | F12: =IF('Ответы на форму (1)'!H11=F$1 ,1, 0) -> 1 | G12: =IF('Ответы на форму (1)'!I11=G$1 ,1, 0) -> 1 | H12: =IF('Ответы на форму (1)'!J11=H$1 ,1, 0) -> 0 | I12: =IF('Ответы на форму (1)'!K11=I$1 ,1, 0) -> 1 | J12: =IF('Ответы на форму (1)'!L11=J$1 ,1, 0) -> 0 | K12: =IF('Ответы на форму (1)'!M11=K$1 ,1, 0) -> 1 | ... AC12: =IF('Ответы на форму (1)'!AE11=AC$1 ,1, 0) -> 0
A13: ='Ответы на форму (1)'!A12 -> 44364.389 | B13: ='Ответы на форму (1)'!B12 -> klimkina.15012004@gmail.com | C13: =SUM(D13:AC13) -> 5 | D13: =IF('Ответы на форму (1)'!F12=D$1 ,1, 0) -> 0 | E13: =IF('Ответы на форму (1)'!G12=E$1 ,1, 0) -> 1 | F13: =IF('Ответы на форму (1)'!H12=F$1 ,1, 0) -> 0 | G13: =IF('Ответы на форму (1)'!I12=G$1 ,1, 0) -> 0 | H13: =IF('Ответы на форму (1)'!J12=H$1 ,1, 0) -> 1 | I13: =IF('Ответы на форму (1)'!K12=I$1 ,1, 0) -> 0 | J13: =IF('Ответы на форму (1)'!L12=J$1 ,1, 0) -> 0 | K13: =IF('Ответы на форму (1)'!M12=K$1 ,1, 0) -> 0 | ... AC13: =IF('Ответы на форму (1)'!AE12=AC$1 ,1, 0) -> 0
A14: ='Ответы на форму (1)'!A13 -> 44364.569 | B14: ='Ответы на форму (1)'!B13 -> ExtrimHack1@mail.ru | C14: =SUM(D14:AC14) -> 4 | D14: =IF('Ответы на форму (1)'!F13=D$1 ,1, 0) -> 1 | E14: =IF('Ответы на форму (1)'!G13=E$1 ,1, 0) -> 1 | F14: =IF('Ответы на форму (1)'!H13=F$1 ,1, 0) -> 0 | G14: =IF('Ответы на форму (1)'!I13=G$1 ,1, 0) -> 0 | H14: =IF('Ответы на форму (1)'!J13=H$1 ,1, 0) -> 0 | I14: =IF('Ответы на форму (1)'!K13=I$1 ,1, 0) -> 0 | J14: =IF('Ответы на форму (1)'!L13=J$1 ,1, 0) -> 0 | K14: =IF('Ответы на форму (1)'!M13=K$1 ,1, 0) -> 0 | ... AC14: =IF('Ответы на форму (1)'!AE13=AC$1 ,1, 0) -> 0
... A19: ='Ответы на форму (1)'!A18 | B19: ='Ответы на форму (1)'!B18 | C19: =SUM(D19:AC19) -> 0 | D19: =IF('Ответы на форму (1)'!F18=D$1 ,1, 0) -> 0 | E19: =IF('Ответы на форму (1)'!G18=E$1 ,1, 0) -> 0 | F19: =IF('Ответы на форму (1)'!H18=F$1 ,1, 0) -> 0 | G19: =IF('Ответы на форму (1)'!I18=G$1 ,1, 0) -> 0 | H19: =IF('Ответы на форму (1)'!J18=H$1 ,1, 0) -> 0 | I19: =IF('Ответы на форму (1)'!K18=I$1 ,1, 0) -> 0 | J19: =IF('Ответы на форму (1)'!L18=J$1 ,1, 0) -> 0 | K19: =IF('Ответы на форму (1)'!M18=K$1 ,1, 0) -> 0 | ... AC19: =IF('Ответы на форму (1)'!AE18=AC$1 ,1, 0) -> 0
A20: ='Ответы на форму (1)'!A20 | B20: ='Ответы на форму (1)'!B20 | C20: =SUM(D20:AC20) -> 0 | D20: =IF('Ответы на форму (1)'!F20=D$1 ,1, 0) -> 0 | E20: =IF('Ответы на форму (1)'!G20=E$1 ,1, 0) -> 0 | F20: =IF('Ответы на форму (1)'!H20=F$1 ,1, 0) -> 0 | G20: =IF('Ответы на форму (1)'!I20=G$1 ,1, 0) -> 0 | H20: =IF('Ответы на форму (1)'!J20=H$1 ,1, 0) -> 0 | I20: =IF('Ответы на форму (1)'!K20=I$1 ,1, 0) -> 0 | J20: =IF('Ответы на форму (1)'!L20=J$1 ,1, 0) -> 0 | K20: =IF('Ответы на форму (1)'!M20=K$1 ,1, 0) -> 0 | ... AC20: =IF('Ответы на форму (1)'!AE20=AC$1 ,1, 0) -> 0
A21: ='Ответы на форму (1)'!A21 | B21: ='Ответы на форму (1)'!B21 | C21: =SUM(D21:AC21) -> 0 | D21: =IF('Ответы на форму (1)'!F21=D$1 ,1, 0) -> 0 | E21: =IF('Ответы на форму (1)'!G21=E$1 ,1, 0) -> 0 | F21: =IF('Ответы на форму (1)'!H21=F$1 ,1, 0) -> 0 | G21: =IF('Ответы на форму (1)'!I21=G$1 ,1, 0) -> 0 | H21: =IF('Ответы на форму (1)'!J21=H$1 ,1, 0) -> 0 | I21: =IF('Ответы на форму (1)'!K21=I$1 ,1, 0) -> 0 | J21: =IF('Ответы на форму (1)'!L21=J$1 ,1, 0) -> 0 | K21: =IF('Ответы на форму (1)'!M21=K$1 ,1, 0) -> 0 | ... AC21: =IF('Ответы на форму (1)'!AE21=AC$1 ,1, 0) -> 0
A22: ='Ответы на форму (1)'!A22 | B22: ='Ответы на форму (1)'!B22 | C22: =SUM(D22:AC22) -> 0 | D22: =IF('Ответы на форму (1)'!F22=D$1 ,1, 0) -> 0 | E22: =IF('Ответы на форму (1)'!G22=E$1 ,1, 0) -> 0 | F22: =IF('Ответы на форму (1)'!H22=F$1 ,1, 0) -> 0 | G22: =IF('Ответы на форму (1)'!I22=G$1 ,1, 0) -> 0 | H22: =IF('Ответы на форму (1)'!J22=H$1 ,1, 0) -> 0 | I22: =IF('Ответы на форму (1)'!K22=I$1 ,1, 0) -> 0 | J22: =IF('Ответы на форму (1)'!L22=J$1 ,1, 0) -> 0 | K22: =IF('Ответы на форму (1)'!M22=K$1 ,1, 0) -> 0 | ... AC22: =IF('Ответы на форму (1)'!AE22=AC$1 ,1, 0) -> 0
A23: ='Ответы на форму (1)'!A23 | B23: ='Ответы на форму (1)'!B23 | C23: =SUM(D23:AC23) -> 0 | D23: =IF('Ответы на форму (1)'!F23=D$1 ,1, 0) -> 0 | E23: =IF('Ответы на форму (1)'!G23=E$1 ,1, 0) -> 0 | F23: =IF('Ответы на форму (1)'!H23=F$1 ,1, 0) -> 0 | G23: =IF('Ответы на форму (1)'!I23=G$1 ,1, 0) -> 0 | H23: =IF('Ответы на форму (1)'!J23=H$1 ,1, 0) -> 0 | I23: =IF('Ответы на форму (1)'!K23=I$1 ,1, 0) -> 0 | J23: =IF('Ответы на форму (1)'!L23=J$1 ,1, 0) -> 0 | K23: =IF('Ответы на форму (1)'!M23=K$1 ,1, 0) -> 0 | ... AC23: =IF('Ответы на форму (1)'!AE23=AC$1 ,1, 0) -> 0
A24: ='Ответы на форму (1)'!A24 | B24: ='Ответы на форму (1)'!B24 | C24: =SUM(D24:AC24) -> 0 | D24: =IF('Ответы на форму (1)'!F24=D$1 ,1, 0) -> 0 | E24: =IF('Ответы на форму (1)'!G24=E$1 ,1, 0) -> 0 | F24: =IF('Ответы на форму (1)'!H24=F$1 ,1, 0) -> 0 | G24: =IF('Ответы на форму (1)'!I24=G$1 ,1, 0) -> 0 | H24: =IF('Ответы на форму (1)'!J24=H$1 ,1, 0) -> 0 | I24: =IF('Ответы на форму (1)'!K24=I$1 ,1, 0) -> 0 | J24: =IF('Ответы на форму (1)'!L24=J$1 ,1, 0) -> 0 | K24: =IF('Ответы на форму (1)'!M24=K$1 ,1, 0) -> 0 | ... AC24: =IF('Ответы на форму (1)'!AE24=AC$1 ,1, 0) -> 0
A25: ='Ответы на форму (1)'!A25 | B25: ='Ответы на форму (1)'!B25 | C25: =SUM(D25:AC25) -> 0 | D25: =IF('Ответы на форму (1)'!F25=D$1 ,1, 0) -> 0 | E25: =IF('Ответы на форму (1)'!G25=E$1 ,1, 0) -> 0 | F25: =IF('Ответы на форму (1)'!H25=F$1 ,1, 0) -> 0 | G25: =IF('Ответы на форму (1)'!I25=G$1 ,1, 0) -> 0 | H25: =IF('Ответы на форму (1)'!J25=H$1 ,1, 0) -> 0 | I25: =IF('Ответы на форму (1)'!K25=I$1 ,1, 0) -> 0 | J25: =IF('Ответы на форму (1)'!L25=J$1 ,1, 0) -> 0 | K25: =IF('Ответы на форму (1)'!M25=K$1 ,1, 0) -> 0 | ... AC25: =IF('Ответы на форму (1)'!AE25=AC$1 ,1, 0) -> 0
A26: ='Ответы на форму (1)'!A26 | B26: ='Ответы на форму (1)'!B26 | C26: =SUM(D26:AC26) -> 0 | D26: =IF('Ответы на форму (1)'!F26=D$1 ,1, 0) -> 0 | E26: =IF('Ответы на форму (1)'!G26=E$1 ,1, 0) -> 0 | F26: =IF('Ответы на форму (1)'!H26=F$1 ,1, 0) -> 0 | G26: =IF('Ответы на форму (1)'!I26=G$1 ,1, 0) -> 0 | H26: =IF('Ответы на форму (1)'!J26=H$1 ,1, 0) -> 0 | I26: =IF('Ответы на форму (1)'!K26=I$1 ,1, 0) -> 0 | J26: =IF('Ответы на форму (1)'!L26=J$1 ,1, 0) -> 0 | K26: =IF('Ответы на форму (1)'!M26=K$1 ,1, 0) -> 0 | ... AC26: =IF('Ответы на форму (1)'!AE26=AC$1 ,1, 0) -> 0
A27: ='Ответы на форму (1)'!A27 | B27: ='Ответы на форму (1)'!B27 | C27: =SUM(D27:AC27) -> 0 | D27: =IF('Ответы на форму (1)'!F27=D$1 ,1, 0) -> 0 | E27: =IF('Ответы на форму (1)'!G27=E$1 ,1, 0) -> 0 | F27: =IF('Ответы на форму (1)'!H27=F$1 ,1, 0) -> 0 | G27: =IF('Ответы на форму (1)'!I27=G$1 ,1, 0) -> 0 | H27: =IF('Ответы на форму (1)'!J27=H$1 ,1, 0) -> 0 | I27: =IF('Ответы на форму (1)'!K27=I$1 ,1, 0) -> 0 | J27: =IF('Ответы на форму (1)'!L27=J$1 ,1, 0) -> 0 | K27: =IF('Ответы на форму (1)'!M27=K$1 ,1, 0) -> 0 | ... AC27: =IF('Ответы на форму (1)'!AE27=AC$1 ,1, 0) -> 0
